Workbook

Sheet Shopping_Data
A1: Employee_ID | B1: Order_ID | C1: Customer_ID | D1: Customer_Name | E1: City | F1: Product | G1: Category | H1: Quantity | I1: Price | J1: Payment_Mode | K1: Shop_Mode | L1: Discount_Percent | M1: Sales_Amount
A2: E01 | B2: 1009 | C2: C109 | D2: Vikas Chopra | E2: Mumbai | F2: Laptop | G2: Electronics | H2: 1 | I2: 65000 | J2: Card | K2: Online | L2: 5 | M2: 61750
A3: E01 | B3: 1001 | C3: C101 | D3: Amit Gupta | E3: Delhi | F3: Laptop | G3: Electronics | H3: 1 | I3: 55000 | J3: Card | K3: Online | L3: 10 | M3: 49500
A4: E02 | B4: 1002 | C4: C102 | D4: Neha Sharma | E4: Mumbai | F4: Mobile | G4: Electronics | H4: 2 | I4: 25000 | J4: UPI | K4: Online | L4: 5 | M4: 47500
A5: E04 | B5: 1010 | C5: C110 | D5: Anjali Thakur | E5: Pune | F5: Sofa | G5: Furniture | H5: 1 | I5: 45000 | J5: UPI | K5: Offline | L5: 10 | M5: 40500
A6: E02 | B6: 1011 | C6: C111 | D6: Rohan Jain | E6: Delhi | F6: Mobile | G6: Electronics | H6: 1 | I6: 30000 | J6: Cash | K6: Online | L6: 5 | M6: 28500
A7: E04 | B7: 1005 | C7: C105 | D7: Arun Jain | E7: Chennai | F7: Table | G7: Furniture | H7: 2 | I7: 12000 | J7: UPI | K7: Offline | L7: 10 | M7: 21600
A8: E05 | B8: 1006 | C8: C106 | D8: Kiran Kaur | E8: Noida | F8: Chair | G8: Furniture | H8: 4 | I8: 5000 | J8: Cash | K8: Offline | L8: 5 | M8: 19000
A9: E03 | B9: 1014 | C9: C114 | D9: Simran Kaur | E9: Mumbai | F9: Watch | G9: Fashion | H9: 2 | I9: 9000 | J9: Cash | K9: Online | L9: 15 | M9: 15300
A10: E03 | B10: 1008 | C10: C108 | D10: Sneha Gupta | E10: Jaipur | F10: Dress | G10: Fashion | H10: 3 | I10: 6000 | J10: Card | K10: Online | L10: 20 | M10: 14400
A11: E05 | B11: 1013 | C11: C113 | D11: Manish Kumar | E11: Chennai | F11: Table | G11: Furniture | H11: 1 | I11: 15000 | J11: Card | K11: Offline | L11: 10 | M11: 13500
A12: E02 | B12: 1015 | C12: C115 | D12: Deepak Arora | E12: Delhi | F12: Headphone | G12: Electronics | H12: 5 | I12: 3000 | J12: UPI | K12: Online | L12: 10 | M12: 13500
A13: E03 | B13: 1003 | C13: C103 | D13: Raj Arora | E13: Pune | F13: Shoes | G13: Fashion | H13: 3 | I13: 3000 | J13: Cash | K13: Offline | L13: 0 | M13: 9000
... A16: E01 | B16: 1004 | C16: C104 | D16: Priya Kalra | E16: Delhi | F16: Watch | G16: Fashion | H16: 1 | I16: 8000 | J16: Card | K16: Online | L16: 15 | M16: 6800
A19: Employee_ID | B19: E01 | C19: E02 | D19: E03 | E19: E01 | F19: E04 | G19: E05 | H19: E02 | I19: E03 | J19: E01 | K19: E04 | L19: E02 | M19: E03 | N19: E05 | O19: E03 | P19: E02
A20: Order_ID | B20: 1001 | C20: 1002 | D20: 1003 | E20: 1004 | F20: 1005 | G20: 1006 | H20: 1007 | I20: 1008 | J20: 1009 | K20: 1010 | L20: 1011 | M20: 1012 | N20: 1013 | O20: 1014 | P20: 1015
A21: Customer_ID | B21: C101 | C21: C102 | D21: C103 | E21: C104 | F21: C105 | G21: C106 | H21: C107 | I21: C108 | J21: C109 | K21: C110 | L21: C111 | M21: C112 | N21: C113 | O21: C114 | P21: C115
A22: Customer_Name | B22: Amit Gupta | C22: Neha Sharma | D22: Raj Arora | E22: Priya Kalra | F22: Arun Jain | G22: Kiran Kaur | H22: Ravi Raj | I22: Sneha Gupta | J22: Vikas Chopra | K22: Anjali Thakur | L22: Rohan Jain | M22: Pooja Bisht | N22: Manish Kumar | O22: Simran Kaur | P22: Deepak Arora
A23: City | B23: Delhi | C23: Mumbai | D23: Pune | E23: Delhi | F23: Chennai | G23: Noida | H23: Delhi | I23: Jaipur | J23: Mumbai | K23: Pune | L23: Delhi | M23: Noida | N23: Chennai | O23: Mumbai | P23: Delhi
A24: Product | B24: Laptop | C24: Mobile | D24: Shoes | E24: Watch | F24: Table | G24: Chair | H24: Headphone | I24: Dress | J24: Laptop | K24: Sofa | L24: Mobile | M24: Shoes | N24: Table | O24: Watch | P24: Headphone
A25: Category | B25: Electronics | C25: Electronics | D25: Fashion | E25: Fashion | F25: Furniture | G25: Furniture | H25: Electronics | I25: Fashion | J25: Electronics | K25: Furniture | L25: Electronics | M25: Fashion | N25: Furniture | O25: Fashion | P25: Electronics
A26: Quantity | B26: 1 | C26: 2 | D26: 3 | E26: 1 | F26: 2 | G26: 4 | H26: 2 | I26: 3 | J26: 1 | K26: 1 | L26: 1 | M26: 2 | N26: 1 | O26: 2 | P26: 5
A27: Price | B27: 55000 | C27: 25000 | D27: 3000 | E27: 8000 | F27: 12000 | G27: 5000 | H27: 4000 | I27: 6000 | J27: 65000 | K27: 45000 | L27: 30000 | M27: 3500 | N27: 15000 | O27: 9000 | P27: 3000
A28: Payment_Mode | B28: Card | C28: UPI | D28: Cash | E28: Card | F28: UPI | G28: Cash | H28: UPI | I28: Card | J28: Card | K28: UPI | L28: Cash | M28: UPI | N28: Card | O28: Cash | P28: UPI
A29: Shop_Mode | B29: Online | C29: Online | D29: Offline | E29: Online | F29: Offline | G29: Offline | H29: Online | I29: Online | J29: Online | K29: Offline | L29: Online | M29: Online | N29: Offline | O29: Online | P29: Online
A30: Discount_Percent | B30: 10 | C30: 5 | D30: 0 | E30: 15 | F30: 10 | G30: 5 | H30: 10 | I30: 20 | J30: 5 | K30: 10 | L30: 5 | M30: 0 | N30: 10 | O30: 15 | P30: 10
A31: Sales_Amount | B31: 49500 | C31: 47500 | D31: 9000 | E31: 6800 | F31: 21600 | G31: 19000 | H31: 7200 | I31: 14400 | J31: 61750 | K31: 40500 | L31: 28500 | M31: 7000 | N31: 13500 | O31: 15300 | P31: 13500

Sheet Lookup_Data
A1: Employee_ID | B1: Employee_Name | C1: City | D1: Payment Mode
A2: E01 | B2: =VLOOKUP($A$2:$A$6,Shopping_Data!$A$2:$D$16,4,) -> Vikas Chopra | C2: =VLOOKUP($A$2:$A$6,Shopping_Data!$A$2:$J$16,5,) -> Mumbai | D2: =VLOOKUP($A$2:$A$6,Shopping_Data!$A$2:$J$16,10,) -> Card
A3: E02 | B3: =VLOOKUP($A$2:$A$6,Shopping_Data!$A$2:$D$16,4,) -> Neha Sharma | C3: =VLOOKUP(A3:A7,Shopping_Data!A3:L17,5,) -> Mumbai | D3: =VLOOKUP($A$2:$A$6,Shopping_Data!$A$2:$J$16,10,) -> UPI
A4: E03 | B4: =VLOOKUP($A$2:$A$6,Shopping_Data!$A$2:$D$16,4,) -> Simran Kaur | C4: =VLOOKUP(A4:A8,Shopping_Data!A4:L18,5,) -> Mumbai | D4: =VLOOKUP($A$2:$A$6,Shopping_Data!$A$2:$J$16,10,) -> Cash
A5: E04 | B5: =VLOOKUP($A$2:$A$6,Shopping_Data!$A$2:$D$16,4,) -> Anjali Thakur | C5: =VLOOKUP(A5:A9,Shopping_Data!A5:L19,5,) -> Pune | D5: =VLOOKUP($A$2:$A$6,Shopping_Data!$A$2:$J$16,10,) -> UPI
A6: E05 | B6: =VLOOKUP($A$2:$A$6,Shopping_Data!$A$2:$D$16,4,) -> Kiran Kaur | C6: =VLOOKUP(A6:A10,Shopping_Data!A6:L20,5,) -> Noida | D6: =VLOOKUP($A$2:$A$6,Shopping_Data!$A$2:$J$16,10,) -> Cash
A9: Employee_ID | B9: E01 | C9: E02 | D9: E03 | E9: E04 | F9: E05
A10: Customer_Name | B10: =HLOOKUP($B$9:$F$9,Shopping_Data!$A$19:$P$31,4,) -> Amit Gupta | C10: =HLOOKUP($B$9:$F$9,Shopping_Data!$A$19:$P$31,4,) -> Neha Sharma | D10: =HLOOKUP($B$9:$F$9,Shopping_Data!$A$19:$P$31,4,) -> Raj Arora | E10: =HLOOKUP($B$9:$F$9,Shopping_Data!$A$19:$P$31,4,) -> Arun Jain | F10: =HLOOKUP($B$9:$F$9,Shopping_Data!$A$19:$P$31,4,) -> Kiran Kaur
A11: City | B11: =HLOOKUP($B$9:$F$9,Shopping_Data!$A$19:$P$31,5,) -> Delhi | C11: =HLOOKUP($B$9:$F$9,Shopping_Data!$A$19:$P$31,5,) -> Mumbai | D11: =HLOOKUP($B$9:$F$9,Shopping_Data!$A$19:$P$31,5,) -> Pune | E11: =HLOOKUP($B$9:$F$9,Shopping_Data!$A$19:$P$31,5,) -> Chennai | F11: =HLOOKUP($B$9:$F$9,Shopping_Data!$A$19:$P$31,5,) -> Noida
A12: Payment Mode | B12: =HLOOKUP($B$9:$F$9,Shopping_Data!$A$19:$P$31,10,) -> Card | C12: =HLOOKUP($B$9:$F$9,Shopping_Data!$A$19:$P$31,10,) -> UPI | D12: =HLOOKUP($B$9:$F$9,Shopping_Data!$A$19:$P$31,10,) -> Cash | E12: =HLOOKUP($B$9:$F$9,Shopping_Data!$A$19:$P$31,10,) -> UPI | F12: =HLOOKUP($B$9:$F$9,Shopping_Data!$A$19:$P$31,10,) -> Cash

Sheet Practice_Questions
A1: Excel Practice Questions | B1: Output using Formulas | C1: To Learn Again
A2: 1. Extract first name from Customer_Name using LEFT function. | B2: =LEFT(Shopping_Data!D2,FIND(" ",Shopping_Data!D2)) -> Vikas
A3: 2. Extract last 3 characters from Customer_ID using RIGHT function. | B3: =RIGHT(Shopping_Data!C2,3) -> 109
A4: 3. Find length of Customer_Name using LEN function. | B4: =LEN(Shopping_Data!D14) -> 8
A5: 4. Convert Customer_Name into uppercase using UPPER function. | B5: =UPPER(Shopping_Data!D10) -> SNEHA GUPTA
A6: 5. Convert Customer_Name into lowercase using LOWER function. | B6: =LOWER(Shopping_Data!D13) -> raj arora
A7: 6. Join Customer_Name and City using CONCAT function. | B7: =CONCATENATE(Shopping_Data!D4," ",Shopping_Data!E4) -> Neha Sharma Mumbai
A8: 7. Join Product and Category using TEXTJOIN function. | B8: - | C8: #N/A
A9: 8. Find position of a character in Customer_Name using FIND. | B9: =FIND("K",Shopping_Data!D5) -> #VALUE!
A10: 9. Extract middle characters using MID function. | B10: =MID(Shopping_Data!D6,LEN(Shopping_Data!D6),3) -> n
A11: 10. Remove extra spaces using TRIM. | B11: =TRIM(Shopping_Data!D11) -> Manish Kumar
A12: 11. Replace text using SUBSTITUTE. | B12: =SUBSTITUTE(Shopping_Data!J4,Shopping_Data!J4,Shopping_Data!J3) -> Card
A13: 12. Search text inside Customer_Name using SEARCH. | B13: - | C13: #N/A
A14: 13. Create Email ID using name + domain. | B14: =CONCATENATE(LEFT(Shopping_Data!D11, FIND(" ",Shopping_Data!D11)-1),".", RIGHT(Shopping_Data!D11, FIND(" ",Shopping_Data!D11)-1), "@","gmail.com") -> Manish. Kumar@gmail.com
A15: 14. Extract first letter from Product name. | B15: =LEFT(Shopping_Data!F5,1) -> S
A16: 15. Extract last letter from City name. | B16: =RIGHT(Shopping_Data!E6,LEN(Shopping_Data!E6)-LEN(Shopping_Data!E6)+1) -> i
A17: 16. Count characters in Product names. | B17: =LEN(Shopping_Data!F2) -> 6
A18: 17. Convert names into proper case using PROPER. | B18: =PROPER("BhaVIk") -> Bhavik
A19: 18. Combine Customer_Name, Product and City in one sentence. | B19: =CONCATENATE(Shopping_Data!D2," ",Shopping_Data!F2," ",Shopping_Data!E2) -> Vikas Chopra Laptop Mumbai
A20: 19. Find customers whose name starts with A. | B20: - | C20: #N/A
A21: 20. Create customer code using LEFT and RIGHT. | B21: =CONCATENATE(UPPER(LEFT(Shopping_Data!D2,FIND(" ",Shopping_Data!D2,1)-1)),RIGHT(Shopping_Data!C2,3),LEFT(Shopping_Data!E2,3)) -> VIKAS109Mum
A22: 21. Find total sales using SUM. | B22: =SUM(Shopping_Data!M2:M16) -> 355050
A23: 22. Find average Sales_Amount using AVERAGE. | B23: =AVERAGE(Shopping_Data!M2:M16) -> 23670
A24: 23. Find highest and lowest Sales_Amount using MAX and MIN. | B24: =MAX(Shopping_Data!M2:M16) -> 61750
A25: 24. Count total orders using COUNT. | B25: =COUNT(Shopping_Data!M2:M16) -> 15
A26: 25. Count Online orders using COUNTIF. | B26: =COUNTIF(Shopping_Data!K2:K16,Shopping_Data!$K$2) -> 10
A27: 26. Find Electronics category sales using SUMIF. | B27: =SUMIF(Shopping_Data!G2:M16,Shopping_Data!$G$2,Shopping_Data!M2:M16) -> 207950
A28: 27. Find sales between two conditions using SUMIFS. | B28: =SUMIFS(Shopping_Data!M2:M16,Shopping_Data!G2:G16,Shopping_Data!$G$4,Shopping_Data!J2:J16,Shopping_Data!$J$3) -> 111250
A29: 28. Find average sales of a specific city using AVERAGEIF. | B29: - | C29: #N/A | D29: AVERAGEIF(Shopping_Data!E2:E16,Shopping_Data!$E$4,Shopping_Data!E2:M16)
A30: 29. Use IF function to create High/Low sales category. | B30: =IF(Shopping_Data!M3>50000,"High", "Low") -> Low
A31: 30. Use nested IF for discount classification. | B31: - | C31: #N/A
A32: 31. Use VLOOKUP to find Employee Name. | B32: Used in Previous Sheet
A33: 32. Use VLOOKUP to find Department. | B33: Used in Previous Sheet
A34: 33. Use XLOOKUP to fetch Manager details. | B34: -
A35: 34. Use HLOOKUP with horizontal employee data. | B35: Used in Previous Sheet
A36: 35. Sort customers by highest sales. | B36: Used in Previous Sheet
A37: 36. Filter only Card payment customers. | B37: Used in Previous Sheet
A38: 37. Find duplicate Customer_ID values. | B38: Used in Previous Sheet
A39: 38. Remove duplicate records. | B39: Used in Previous Sheet
A40: 39. Apply conditional formatting for high sales. | B40: Used in Previous Sheet
...
